Workbook

Sheet summary
A2: Table 1: Breakdown by status of submission
A3: Status of Submission | B3: Number of firms | C3: Number of firms -investment schemes
A4: No records | B4: =SUMIFS('2.masterfirm'!E:E,'2.masterfirm'!$G:$G,$A4) -> 68 | C4: =SUMIFS('2.masterfirm'!F:F,'2.masterfirm'!$G:$G,$A4) -> 69
A5: Have records but not submitted | B5: =SUMIFS('2.masterfirm'!E:E,'2.masterfirm'!$G:$G,$A5) -> 62 | C5: =SUMIFS('2.masterfirm'!F:F,'2.masterfirm'!$G:$G,$A5) -> 159
A6: Have records and have submitted | B6: =SUMIFS('2.masterfirm'!E:E,'2.masterfirm'!$G:$G,$A6) -> 30 | C6: =SUMIFS('2.masterfirm'!F:F,'2.masterfirm'!$G:$G,$A6) -> 30
A7: Total | B7: =SUM(B4:B6) -> 160 | C7: =SUM(C4:C6) -> 258
A10: Status of Submission | B10: Number of firms | C10: Number of firms -investment schemes
A11: No records | B11: =B4/B$7 -> 0.425 | C11: =C4/C$7 -> 0.26744186
A12: Have records but not submitted | B12: =B5/B$7 -> 0.3875 | C12: =C5/C$7 -> 0.61627907
A13: Have records and have submitted | B13: =B6/B$7 -> 0.1875 | C13: =C6/C$7 -> 0.11627907
A14: Total | B14: =SUM(B11:B13) -> 1 | C14: =SUM(C11:C13) -> 1
A17: Table 2: Breakdown by industry
A18: Sector | B18: Industry | C18: Number of unreported firms | D18: Number of reported firms | E18: Number of firms | F18: %
A19: Financial Sector | B19: Australian/NZ Bank | C19: =E19-D19 -> 8 | D19: =SUMIFS('2.masterfirm'!E:E,'2.masterfirm'!C:C,summary!B19,'2.masterfirm'!G:G,summary!$A$13) -> 2 | E19: =SUMIFS('2.masterfirm'!E:E,'2.masterfirm'!C:C,summary!B19) -> 10 | F19: =D19/E19 -> 0.2
B20: Foreign Bank | C20: =E20-D20 -> 3 | D20: =SUMIFS('2.masterfirm'!E:E,'2.masterfirm'!C:C,summary!B20,'2.masterfirm'!G:G,summary!$A$13) -> 7 | E20: =SUMIFS('2.masterfirm'!E:E,'2.masterfirm'!C:C,summary!B20) -> 10 | F20: =D20/E20 -> 0.7
B21: Finance/investment | C21: =E21-D21 -> 39 | D21: =SUMIFS('2.masterfirm'!E:E,'2.masterfirm'!C:C,summary!B21,'2.masterfirm'!G:G,summary!$A$13) -> 3 | E21: =SUMIFS('2.masterfirm'!E:E,'2.masterfirm'!C:C,summary!B21) -> 42 | F21: =D21/E21 -> 0.071428571
B22: Insurance | C22: =E22-D22 -> 12 | D22: =SUMIFS('2.masterfirm'!E:E,'2.masterfirm'!C:C,summary!B22,'2.masterfirm'!G:G,summary!$A$13) -> 4 | E22: =SUMIFS('2.masterfirm'!E:E,'2.masterfirm'!C:C,summary!B22) -> 16 | F22: =D22/E22 -> 0.25
A23: Real Estate | B23: Property | C23: =E23-D23 -> 9 | D23: =SUMIFS('2.masterfirm'!E:E,'2.masterfirm'!C:C,summary!B23,'2.masterfirm'!G:G,summary!$A$13) -> 2 | E23: =SUMIFS('2.masterfirm'!E:E,'2.masterfirm'!C:C,summary!B23) -> 11 | F23: =D23/E23 -> 0.18181818
B24: Building | C24: =E24-D24 -> 3 | D24: =SUMIFS('2.masterfirm'!E:E,'2.masterfirm'!C:C,summary!B24,'2.masterfirm'!G:G,summary!$A$13) -> 0 | E24: =SUMIFS('2.masterfirm'!E:E,'2.masterfirm'!C:C,summary!B24) -> 3 | F24: =D24/E24 -> 0
B25: Age Care | C25: =E25-D25 -> 2 | D25: =SUMIFS('2.masterfirm'!E:E,'2.masterfirm'!C:C,summary!B25,'2.masterfirm'!G:G,summary!$A$13) -> 1 | E25: =SUMIFS('2.masterfirm'!E:E,'2.masterfirm'!C:C,summary!B25) -> 3 | F25: =D25/E25 -> 0.33333333
A26: Energy | B26: Energy | C26: =E26-D26 -> 8 | D26: =SUMIFS('2.masterfirm'!E:E,'2.masterfirm'!C:C,summary!B26,'2.masterfirm'!G:G,summary!$A$13) -> 1 | E26: =SUMIFS('2.masterfirm'!E:E,'2.masterfirm'!C:C,summary!B26) -> 9 | F26: =D26/E26 -> 0.11111111
A27: Agricuture | B27: Food/Agriculture | C27: =E27-D27 -> 9 | D27: =SUMIFS('2.masterfirm'!E:E,'2.masterfirm'!C:C,summary!B27,'2.masterfirm'!G:G,summary!$A$13) -> 3 | E27: =SUMIFS('2.masterfirm'!E:E,'2.masterfirm'!C:C,summary!B27) -> 12 | F27: =D27/E27 -> 0.25
A28: Industry | B28: Consumer | C28: =E28-D28 -> 1 | D28: =SUMIFS('2.masterfirm'!E:E,'2.masterfirm'!C:C,summary!B28,'2.masterfirm'!G:G,summary!$A$13) -> 1 | E28: =SUMIFS('2.masterfirm'!E:E,'2.masterfirm'!C:C,summary!B28) -> 2 | F28: =D28/E28 -> 0.5
B29: Hotel/Restaurant/Tourism | C29: =E29-D29 -> 1 | D29: =SUMIFS('2.masterfirm'!E:E,'2.masterfirm'!C:C,summary!B29,'2.masterfirm'!G:G,summary!$A$13) -> 2 | E29: =SUMIFS('2.masterfirm'!E:E,'2.masterfirm'!C:C,summary!B29) -> 3 | F29: =D29/E29 -> 0.66666667
B30: Airport/infrastructure | C30: =E30-D30 -> 7 | D30: =SUMIFS('2.masterfirm'!E:E,'2.masterfirm'!C:C,summary!B30,'2.masterfirm'!G:G,summary!$A$13) -> 2 | E30: =SUMIFS('2.masterfirm'!E:E,'2.masterfirm'!C:C,summary!B30) -> 9 | F30: =D30/E30 -> 0.22222222
B31: Transportation | C31: =E31-D31 -> 6 | D31: =SUMIFS('2.masterfirm'!E:E,'2.masterfirm'!C:C,summary!B31,'2.masterfirm'!G:G,summary!$A$13) -> 0 | E31: =SUMIFS('2.masterfirm'!E:E,'2.masterfirm'!C:C,summary!B31) -> 6 | F31: =D31/E31 -> 0
B32: Government | C32: =E32-D32 -> 2 | D32: =SUMIFS('2.masterfirm'!E:E,'2.masterfirm'!C:C,summary!B32,'2.masterfirm'!G:G,summary!$A$13) -> 0 | E32: =SUMIFS('2.masterfirm'!E:E,'2.masterfirm'!C:C,summary!B32) -> 2 | F32: =D32/E32 -> 0
B33: Manufacturing | C33: =E33-D33 -> 5 | D33: =SUMIFS('2.masterfirm'!E:E,'2.masterfirm'!C:C,summary!B33,'2.masterfirm'!G:G,summary!$A$13) -> 0 | E33: =SUMIFS('2.masterfirm'!E:E,'2.masterfirm'!C:C,summary!B33) -> 5 | F33: =D33/E33 -> 0
B34: Healthcare | C34: =E34-D34 -> 6 | D34: =SUMIFS('2.masterfirm'!E:E,'2.masterfirm'!C:C,summary!B34,'2.masterfirm'!G:G,summary!$A$13) -> 0 | E34: =SUMIFS('2.masterfirm'!E:E,'2.masterfirm'!C:C,summary!B34) -> 6 | F34: =D34/E34 -> 0
A35: IT | B35: Technology | C35: =E35-D35 -> 5 | D35: =SUMIFS('2.masterfirm'!E:E,'2.masterfirm'!C:C,summary!B35,'2.masterfirm'!G:G,summary!$A$13) -> 2 | E35: =SUMIFS('2.masterfirm'!E:E,'2.masterfirm'!C:C,summary!B35) -> 7 | F35: =D35/E35 -> 0.28571429
B36: Telecommunications | C36: =E36-D36 -> 4 | D36: =SUMIFS('2.masterfirm'!E:E,'2.masterfirm'!C:C,summary!B36,'2.masterfirm'!G:G,summary!$A$13) -> 0 | E36: =SUMIFS('2.masterfirm'!E:E,'2.masterfirm'!C:C,summary!B36) -> 4 | F36: =D36/E36 -> 0
C37: =SUM(C19:C36) -> 130 | D37: =SUM(D19:D36) -> 30 | E37: =SUM(E19:E36) -> 160 | F37: =D37/E37 -> 0.1875
A40: Table 3: Breakdown by sector
A41: Industry | B41: Industry | C41: Number of unreported firms | D41: Number of reported firms | E41: Number of firms | F41: %
A42: Financial Sector | B42: =A42 -> Financial Sector | C42: =SUM(C19:C22) -> 62 | D42: =SUM(D19:D22) -> 16 | E42: =SUM(E19:E22) -> 78 | F42: =D42/E42 -> 0.20512821
A43: Real Estate | B43: =A43 -> Real Estate | C43: =E43-D43 -> 0 | D43: =SUMIFS('2.masterfirm'!E:E,'2.masterfirm'!C:C,summary!B43,'2.masterfirm'!G:G,summary!$A$13) -> 0 | E43: =SUMIFS('2.masterfirm'!E:E,'2.masterfirm'!C:C,summary!B43) -> 0 | F43: =D43/E43 -> #DIV/0!
A44: Energy | B44: =A44 -> Energy | C44: =C26 -> 8 | D44: =D26 -> 1 | E44: =E26 -> 9 | F44: =D44/E44 -> 0.11111111
A45: Agricuture | B45: =A45 -> Agricuture | C45: =C27 -> 9 | D45: =D27 -> 3 | E45: =E27 -> 12 | F45: =D45/E45 -> 0.25
A46: Industry | B46: =A46 -> Industry | C46: =SUM(C28:C33) -> 22 | D46: =SUM(D28:D33) -> 5 | E46: =SUM(E28:E33) -> 27 | F46: =D46/E46 -> 0.18518519
A47: Telecommunication & Technology & Healthcare | B47: Telecommunication & Technology & Healthcare | C47: =SUM(C35:C36) -> 9 | D47: =SUM(D35:D36) -> 2 | E47: =SUM(E35:E36) -> 11 | F47: =D47/E47 -> 0.18181818
...

Sheet 20April
B1: Link | C1: Company Name | D1: Text | E1: text_new | F1: Scheme Name | G1: status | H1: scheme | I1: Submit Date | J1: Due Date
A2: 0 | B2: https://crd-app.companiesoffice.govt.nz/dashboard/reportingentity/?id=8b6b5ca5-8394-ee11-be37-00224892b34a | C2: AA INSURANCE LIMITED | D2: Reporting Period . sort descending Actions There are no records to display. | E2: There are no records to display. | G2: No records | H2: Company | I2: no data | J2: no data
A3: 1 | B3: https://crd-app.companiesoffice.govt.nz/dashboard/reportingentity/?id=a96b5ca5-8394-ee11-be37-00224892b34a | C3: AFT PHARMACEUTICALS LIMITED | D3: Reporting Period . sort descending Actions 31-03-2024 - Due by 31-07-2024 | E3: 31-03-2024 - Due by 31-07-2024 | G3: Have records but not submitted | H3: Company | I3: 45382 | J3: 45504
A4: 2 | B4: https://crd-app.companiesoffice.govt.nz/dashboard/reportingentity/?id=8d6b5ca5-8394-ee11-be37-00224892b34a | C4: AIA NEW ZEALAND LIMITED | D4: Reporting Period . sort descending Actions 31-12-2023 - Due by 30-04-2024 | E4: 31-12-2023 - Due by 30-04-2024 | G4: Have records but not submitted | H4: Company | I4: 45291 | J4: 45412
A5: 3 | B5: https://crd-app.companiesoffice.govt.nz/dashboard/reportingentity/?id=ab6b5ca5-8394-ee11-be37-00224892b34a | C5: AIR NEW ZEALAND LIMITED | D5: Reporting Period . sort descending Actions There are no records to display. | E5: There are no records to display. | G5: No records | H5: Company | I5: no data | J5: no data
A6: 4 | B6: https://crd-app.companiesoffice.govt.nz/dashboard/reportingentity/?id=ad6b5ca5-8394-ee11-be37-00224892b34a | C6: ARBORGEN HOLDINGS LIMITED | D6: Reporting Period . sort descending Actions 31-03-2024 - Due by 31-07-2024 | E6: 31-03-2024 - Due by 31-07-2024 | G6: Have records but not submitted | H6: Company | I6: 45382 | J6: 45504
A7: 5 | B7: https://crd-app.companiesoffice.govt.nz/dashboard/reportingentity/?id=af6b5ca5-8394-ee11-be37-00224892b34a | C7: ARGOSY PROPERTY LIMITED | D7: Reporting Period . sort descending Actions 31-03-2024 - Due by 31-07-2024 | E7: 31-03-2024 - Due by 31-07-2024 | G7: Have records but not submitted | H7: Company | I7: 45382 | J7: 45504
A8: 6 | B8: https://crd-app.companiesoffice.govt.nz/dashboard/reportingentity/?id=b16b5ca5-8394-ee11-be37-00224892b34a | C8: ARVIDA GROUP LIMITED | D8: Reporting Period . sort descending Actions 31-03-2024 - Due by 31-07-2024 | E8: 31-03-2024 - Due by 31-07-2024 | G8: Have records but not submitted | H8: Company | I8: 45382 | J8: 45504
A9: 7 | B9: https://crd-app.companiesoffice.govt.nz/dashboard/reportingentity/?id=656b5ca5-8394-ee11-be37-00224892b34a | C9: ASB BANK LIMITED | D9: Reporting Period . sort descending Actions There are no records to display. | E9: There are no records to display. | G9: No records | H9: Company | I9: no data | J9: no data
A10: 8 | B10: https://crd-app.companiesoffice.govt.nz/dashboard/reportingentity/?id=b36b5ca5-8394-ee11-be37-00224892b34a | C10: ASSET PLUS LIMITED | D10: Reporting Period . sort descending Actions 31-03-2024 - Due by 31-07-2024 | E10: 31-03-2024 - Due by 31-07-2024 | G10: Have records but not submitted | H10: Company | I10: 45382 | J10: 45504
A11: 9 | B11: https://crd-app.companiesoffice.govt.nz/dashboard/reportingentity/?id=8f6b5ca5-8394-ee11-be37-00224892b34a | C11: ASTERON LIFE LIMITED | D11: Reporting Period . sort descending Actions There are no records to display. | E11: There are no records to display. | G11: No records | H11: Company | I11: no data | J11: no data
A12: 10 | B12: https://crd-app.companiesoffice.govt.nz/dashboard/reportingentity/?id=b56b5ca5-8394-ee11-be37-00224892b34a | C12: AUCKLAND COUNCIL | D12: Reporting Period . sort descending Actions There are no records to display. | E12: There are no records to display. | G12: No records | H12: Company | I12: no data | J12: no data
A13: 11 | B13: https://crd-app.companiesoffice.govt.nz/dashboard/reportingentity/?id=b76b5ca5-8394-ee11-be37-00224892b34a | C13: AUCKLAND INTERNATIONAL AIRPORT LIMITED | D13: Reporting Period . sort descending Actions There are no records to display. | E13: There are no records to display. | G13: No records | H13: Company | I13: no data | J13: no data
A14: 12 | B14: https://crd-app.companiesoffice.govt.nz/dashboard/reportingentity/?id=b96b5ca5-8394-ee11-be37-00224892b34a | C14: AUSTRALIAN FOUNDATION INVESTMENT COMPANY LIMITED | D14: Reporting Period . sort descending Actions There are no records to display. | E14: There are no records to display. | G14: No records | H14: Company | I14: no data | J14: no data
A15: 13 | B15: https://crd-app.companiesoffice.govt.nz/dashboard/reportingentity/?id=676b5ca5-8394-ee11-be37-00224892b34a | C15: BANK OF CHINA (NEW ZEALAND) LIMITED | D15: Reporting Period . sort descending Actions 31-12-2023 - Due by 30-04-2024 | E15: 31-12-2023 - Due by 30-04-2024 | G15: Have records but not submitted | H15: Company | I15: 45291 | J15: 45412
A16: 14 | B16: https://crd-app.companiesoffice.govt.nz/dashboard/reportingentity/?id=696b5ca5-8394-ee11-be37-00224892b34a | C16: BANK OF CHINA LIMITED | D16: Reporting Period . sort descending Actions 31-12-2023 - Due by 30-04-2024 | E16: 31-12-2023 - Due by 30-04-2024 | G16: Have records but not submitted | H16: Company | I16: 45291 | J16: 45412
A17: 15 | B17: https://crd-app.companiesoffice.govt.nz/dashboard/reportingentity/?id=bb6b5ca5-8394-ee11-be37-00224892b34a | C17: BARRAMUNDI LIMITED | D17: Reporting Period . sort descending Actions There are no records to display. | E17: There are no records to display. | G17: No records | H17: Company | I17: no data | J17: no data
A18: 16 | B18: https://crd-app.companiesoffice.govt.nz/dashboard/reportingentity/?id=bd6b5ca5-8394-ee11-be37-00224892b34a | C18: BRISCOE GROUP LIMITED | D18: Reporting Period . sort descending Actions 31-01-2024 - Click to view Climate Statement/s | E18: 31-01-2024 - Click to view Climate Statement/s | G18: Have records and have submitted | H18: Company | I18: no data | J18: no data
A19: 17 | B19: https://crd-app.companiesoffice.govt.nz/dashboard/reportingentity/?id=bf6b5ca5-8394-ee11-be37-00224892b34a | C19: CDL INVESTMENTS NEW ZEALAND LIMITED | D19: Reporting Period . sort descending Actions 31-12-2023 - Click to view Climate Statement/s | E19: 31-12-2023 - Click to view Climate Statement/s | G19: Have records and have submitted | H19: Company | I19: no data | J19: no data
A20: 18 | B20: https://crd-app.companiesoffice.govt.nz/dashboard/reportingentity/?id=c16b5ca5-8394-ee11-be37-00224892b34a | C20: CHANNEL INFRASTRUCTURE NZ LIMITED | D20: Reporting Period . sort descending Actions 31-12-2023 - Click to view Climate Statement/s | E20: 31-12-2023 - Click to view Climate Statement/s | G20: Have records and have submitted | H20: Company | I20: no data | J20: no data
A21: 19 | B21: https://crd-app.companiesoffice.govt.nz/dashboard/reportingentity/?id=6b6b5ca5-8394-ee11-be37-00224892b34a | C21: CHINA CONSTRUCTION BANK (NEW ZEALAND) LIMITED | D21: Reporting Period . sort descending Actions 31-12-2023 - Due by 30-04-2024 | E21: 31-12-2023 - Due by 30-04-2024 | G21: Have records but not submitted | H21: Company | I21: 45291 | J21: 45412
A22: 20 | B22: https://crd-app.companiesoffice.govt.nz/dashboard/reportingentity/?id=6d6b5ca5-8394-ee11-be37-00224892b34a | C22: CHINA CONSTRUCTION BANK CORPORATION | D22: Reporting Period . sort descending Actions 31-12-2023 - Due by 30-04-2024 | E22: 31-12-2023 - Due by 30-04-2024 | G22: Have records but not submitted | H22: Company | I22: 45291 | J22: 45412
A23: 21 | B23: https://crd-app.companiesoffice.govt.nz/dashboard/reportingentity/?id=c36b5ca5-8394-ee11-be37-00224892b34a | C23: CHORUS LIMITED | D23: Reporting Period . sort descending Actions There are no records to display. | E23: There are no records to display. | G23: No records | H23: Company | I23: no data | J23: no data
A24: 22 | B24: https://crd-app.companiesoffice.govt.nz/dashboard/reportingentity/?id=c56b5ca5-8394-ee11-be37-00224892b34a | C24: CHRISTCHURCH CITY HOLDINGS LIMITED | D24: Reporting Period . sort descending Actions There are no records to display. | E24: There are no records to display. | G24: No records | H24: Company | I24: no data | J24: no data
A25: 23 | B25: https://crd-app.companiesoffice.govt.nz/dashboard/reportingentity/?id=c76b5ca5-8394-ee11-be37-00224892b34a | C25: CHRISTCHURCH INTERNATIONAL AIRPORT LIMITED | D25: Reporting Period . sort descending Actions There are no records to display. | E25: There are no records to display. | G25: No records | H25: Company | I25: no data | J25: no data
A26: 24 | B26: https://crd-app.companiesoffice.govt.nz/dashboard/reportingentity/?id=916b5ca5-8394-ee11-be37-00224892b34a | C26: CHUBB LIFE INSURANCE NEW ZEALAND LIMITED | D26: Reporting Period . sort descending Actions 31-12-2023 - Due by 30-04-2024 | E26: 31-12-2023 - Due by 30-04-2024 | G26: Have records but not submitted | H26: Company | I26: 45291 | J26: 45412
A27: 25 | B27: https://crd-app.companiesoffice.govt.nz/dashboard/reportingentity/?id=6f6b5ca5-8394-ee11-be37-00224892b34a | C27: CITIBANK, N.A. | D27: Reporting Period . sort descending Actions 31-12-2023 - Due by 30-04-2024 | E27: 31-12-2023 - Due by 30-04-2024 | G27: Have records but not submitted | H27: Company | I27: 45291 | J27: 45412
A28: 26 | B28: https://crd-app.companiesoffice.govt.nz/dashboard/reportingentity/?id=716b5ca5-8394-ee11-be37-00224892b34a | C28: COMMONWEALTH BANK OF AUSTRALIA | D28: Reporting Period . sort descending Actions There are no records to display. | E28: There are no records to display. | G28: No records | H28: Company | I28: no data | J28: no data
A29: 27 | B29: https://crd-app.companiesoffice.govt.nz/dashboard/reportingentity/?id=c96b5ca5-8394-ee11-be37-00224892b34a | C29: COMVITA LIMITED | D29: Reporting Period . sort descending Actions There are no records to display. | E29: There are no records to display. | G29: No records | H29: Company | I29: no data | J29: no data
A30: 28 | B30: https://crd-app.companiesoffice.govt.nz/dashboard/reportingentity/?id=cb6b5ca5-8394-ee11-be37-00224892b34a | C30: CONTACT ENERGY LIMITED | D30: Reporting Period . sort descending Actions There are no records to display. | E30: There are no records to display. | G30: No records | H30: Company | I30: no data | J30: no data
A31: 29 | B31: https://crd-app.companiesoffice.govt.nz/dashboard/reportingentity/?id=736b5ca5-8394-ee11-be37-00224892b34a | C31: COOPERATIEVE RABOBANK U.A. | D31: Reporting Period . sort descending Actions 31-12-2023 - Due by 30-04-2024 | E31: 31-12-2023 - Due by 30-04-2024 | G31: Have records but not submitted | H31: Company | I31: 45291 | J31: 45412
A32: 30 | B32: https://crd-app.companiesoffice.govt.nz/dashboard/reportingentity/?id=cd6b5ca5-8394-ee11-be37-00224892b34a | C32: DELEGAT GROUP LIMITED | D32: Reporting Period . sort descending Actions There are no records to display. | E32: There are no records to display. | G32: No records | H32: Company | I32: no data | J32: no data
A33: 31 | B33: https://crd-app.companiesoffice.govt.nz/dashboard/reportingentity/?id=cf6b5ca5-8394-ee11-be37-00224892b34a | C33: EBOS GROUP LIMITED | D33: Reporting Period . sort descending Actions There are no records to display. | E33: There are no records to display. | G33: No records | H33: Company | I33: no data | J33: no data
A34: 32 | B34: https://crd-app.companiesoffice.govt.nz/dashboard/reportingentity/?id=d16b5ca5-8394-ee11-be37-00224892b34a | C34: EROAD LIMITED | D34: Reporting Period . sort descending Actions 31-03-2024 - Due by 31-07-2024 | E34: 31-03-2024 - Due by 31-07-2024 | G34: Have records but not submitted | H34: Company | I34: 45382 | J34: 45504
A35: 33 | B35: https://crd-app.companiesoffice.govt.nz/dashboard/reportingentity/?id=d36b5ca5-8394-ee11-be37-00224892b34a | C35: F&C INVESTMENT TRUST PLC | D35: Reporting Period . sort descending Actions 31-12-2023 - Due by 30-04-2024 | E35: 31-12-2023 - Due by 30-04-2024 | G35: Have records but not submitted | H35: Company | I35: 45291 | J35: 45412
A36: 34 | B36: https://crd-app.companiesoffice.govt.nz/dashboard/reportingentity/?id=936b5ca5-8394-ee11-be37-00224892b34a | C36: FIDELITY LIFE ASSURANCE COMPANY LIMITED | D36: Reporting Period . sort descending Actions There are no records to display. | E36: There are no records to display. | G36: No records | H36: Company | I36: no data | J36: no data
A37: 35 | B37: https://crd-app.companiesoffice.govt.nz/dashboard/reportingentity/?id=d56b5ca5-8394-ee11-be37-00224892b34a | C37: FISHER & PAYKEL HEALTHCARE CORPORATION LIMITED | D37: Reporting Period . sort descending Actions 31-03-2024 - Due by 31-07-2024 | E37: 31-03-2024 - Due by 31-07-2024 | G37: Have records but not submitted | H37: Company | I37: 45382 | J37: 45504
A38: 36 | B38: https://crd-app.companiesoffice.govt.nz/dashboard/reportingentity/?id=d76b5ca5-8394-ee11-be37-00224892b34a | C38: FLETCHER BUILDING INDUSTRIES LIMITED | D38: Reporting Period . sort descending Actions There are no records to display. | E38: There are no records to display. | G38: No records | H38: Company | I38: no data | J38: no data
A39: 37 | B39: https://crd-app.companiesoffice.govt.nz/dashboard/reportingentity/?id=d96b5ca5-8394-ee11-be37-00224892b34a | C39: FLETCHER BUILDING LIMITED | D39: Reporting Period . sort descending Actions There are no records to display. | E39: There are no records to display. | G39: No records | H39: Company | I39: no data | J39: no data
A40: 38 | B40: https://crd-app.companiesoffice.govt.nz/dashboard/reportingentity/?id=956b5ca5-8394-ee11-be37-00224892b34a | C40: FMG INSURANCE LIMITED | D40: Reporting Period . sort descending Actions 31-03-2024 - Due by 31-07-2024 | E40: 31-03-2024 - Due by 31-07-2024 | G40: Have records but not submitted | H40: Company | I40: 45382 | J40: 45504
...

Sheet 1.master_list_7May
B1: Link | C1: Company Name | D1: Text | E1: text_new | F1: Scheme Name | G1: status | H1: scheme | I1: Due Date | J1: Submit Date | K1: Status on April
A2: 0 | B2: https://crd-app.companiesoffice.govt.nz/dashboard/reportingentity/?id=8b6b5ca5-8394-ee11-be37-00224892b34a | C2: AA INSURANCE LIMITED | D2: Reporting Period . sort descending Actions There are no records to display. | E2: There are no records to display. | G2: No records | H2: Company | K2: =VLOOKUP(B2,'20April'!B:G,6,0) -> No records
A3: 1 | B3: https://crd-app.companiesoffice.govt.nz/dashboard/reportingentity/?id=a96b5ca5-8394-ee11-be37-00224892b34a | C3: AFT PHARMACEUTICALS LIMITED | D3: Reporting Period . sort descending Actions 31-03-2024 - Due by 31-07-2024 | E3: 31-03-2024 - Due by 31-07-2024 | G3: Have records but not submitted | H3: Company | I3: 45382 | J3: 45504 | K3: =VLOOKUP(B3,'20April'!B:G,6,0) -> Have records but not submitted
A4: 2 | B4: https://crd-app.companiesoffice.govt.nz/dashboard/reportingentity/?id=8d6b5ca5-8394-ee11-be37-00224892b34a | C4: AIA NEW ZEALAND LIMITED | D4: Reporting Period . sort descending Actions 31-12-2023 - Click to view Climate Statement/s | E4: 31-12-2023 - Click to view Climate Statement/s | G4: Have records and have submitted | H4: Company | K4: =VLOOKUP(B4,'20April'!B:G,6,0) -> Have records but not submitted
A5: 3 | B5: https://crd-app.companiesoffice.govt.nz/dashboard/reportingentity/?id=ab6b5ca5-8394-ee11-be37-00224892b34a | C5: AIR NEW ZEALAND LIMITED | D5: Reporting Period . sort descending Actions There are no records to display. | E5: There are no records to display. | G5: No records | H5: Company | K5: =VLOOKUP(B5,'20April'!B:G,6,0) -> No records
A6: 135 | B6: https://crd-app.companiesoffice.govt.nz/dashboard/reportingentity/scheme/?id=ff5ba035-8a94-ee11-be37-00224892b34a&refentity=mbie_reportingentity&refid=696c5ca5-8394-ee11-be37-00224892b34a&refrel=mbie_Scheme_ReportingEntityId_mbie_Report | C6: AMP WEALTH MANAGEMENT NEW ZEALAND LIMITED | D6: Reporting Period . sort descending Actions 31-03-2024 - Due by 31-07-2024 | E6: 31-03-2024 - Due by 31-07-2024 | F6: AMP INVESTMENT TRUST (SCH10721) | G6: Have records but not submitted | H6: Investment Scheme | I6: 45382 | J6: 45504 | K6: =VLOOKUP(B6,'20April'!B:G,6,0) -> Have records but not submitted
A7: 136 | B7: https://crd-app.companiesoffice.govt.nz/dashboard/reportingentity/scheme/?id=fd5ba035-8a94-ee11-be37-00224892b34a&refentity=mbie_reportingentity&refid=696c5ca5-8394-ee11-be37-00224892b34a&refrel=mbie_Scheme_ReportingEntityId_mbie_Report | C7: AMP WEALTH MANAGEMENT NEW ZEALAND LIMITED | D7: Reporting Period . sort descending Actions 31-03-2024 - Due by 31-07-2024 | E7: 31-03-2024 - Due by 31-07-2024 | F7: AMP KIWISAVER SCHEME (SCH10367) | G7: Have records but not submitted | H7: Investment Scheme | I7: 45382 | J7: 45504 | K7: =VLOOKUP(B7,'20April'!B:G,6,0) -> Have records but not submitted
A8: 137 | B8: https://crd-app.companiesoffice.govt.nz/dashboard/reportingentity/scheme/?id=095ca035-8a94-ee11-be37-00224892b34a&refentity=mbie_reportingentity&refid=696c5ca5-8394-ee11-be37-00224892b34a&refrel=mbie_Scheme_ReportingEntityId_mbie_Report | C8: AMP WEALTH MANAGEMENT NEW ZEALAND LIMITED | D8: Reporting Period . sort descending Actions 31-03-2024 - Due by 31-07-2024 | E8: 31-03-2024 - Due by 31-07-2024 | F8: AMP MANAGED FUNDS (SCH13265) | G8: Have records but not submitted | H8: Investment Scheme | I8: 45382 | J8: 45504 | K8: =VLOOKUP(B8,'20April'!B:G,6,0) -> Have records but not submitted
A9: 138 | B9: https://crd-app.companiesoffice.govt.nz/dashboard/reportingentity/scheme/?id=035ca035-8a94-ee11-be37-00224892b34a&refentity=mbie_reportingentity&refid=696c5ca5-8394-ee11-be37-00224892b34a&refrel=mbie_Scheme_ReportingEntityId_mbie_Report | C9: AMP WEALTH MANAGEMENT NEW ZEALAND LIMITED | D9: Reporting Period . sort descending Actions 31-03-2024 - Due by 31-07-2024 | E9: 31-03-2024 - Due by 31-07-2024 | F9: AMP PASSIVE PERSONAL RETIREMENT PLAN - INTERNATIONAL PASSIVE SHARES INVESTMENT FUND (SCH10821) | G9: Have records but not submitted | H9: Investment Scheme | I9: 45382 | J9: 45504 | K9: =VLOOKUP(B9,'20April'!B:G,6,0) -> Have records but not submitted
A10: 139 | B10: https://crd-app.companiesoffice.govt.nz/dashboard/reportingentity/scheme/?id=055ca035-8a94-ee11-be37-00224892b34a&refentity=mbie_reportingentity&refid=696c5ca5-8394-ee11-be37-00224892b34a&refrel=mbie_Scheme_ReportingEntityId_mbie_Report | C10: AMP WEALTH MANAGEMENT NEW ZEALAND LIMITED | D10: Reporting Period . sort descending Actions 31-03-2024 - Due by 31-07-2024 | E10: 31-03-2024 - Due by 31-07-2024 | F10: AMP PASSIVE PERSONAL RETIREMENT PLAN - NEW ZEALAND PASSIVE SHARES INVESTMENT FUND (SCH10822) | G10: Have records but not submitted | H10: Investment Scheme | I10: 45382 | J10: 45504 | K10: =VLOOKUP(B10,'20April'!B:G,6,0) -> Have records but not submitted
A11: 140 | B11: https://crd-app.companiesoffice.govt.nz/dashboard/reportingentity/scheme/?id=015ca035-8a94-ee11-be37-00224892b34a&refentity=mbie_reportingentity&refid=696c5ca5-8394-ee11-be37-00224892b34a&refrel=mbie_Scheme_ReportingEntityId_mbie_Report | C11: AMP WEALTH MANAGEMENT NEW ZEALAND LIMITED | D11: Reporting Period . sort descending Actions 31-03-2024 - Due by 31-07-2024 | E11: 31-03-2024 - Due by 31-07-2024 | F11: AMP PERSONAL RETIREMENT PLAN (SCH10820) | G11: Have records but not submitted | H11: Investment Scheme | I11: 45382 | J11: 45504 | K11: =VLOOKUP(B11,'20April'!B:G,6,0) -> Have records but not submitted
A12: 141 | B12: https://crd-app.companiesoffice.govt.nz/dashboard/reportingentity/scheme/?id=075ca035-8a94-ee11-be37-00224892b34a&refentity=mbie_reportingentity&refid=696c5ca5-8394-ee11-be37-00224892b34a&refrel=mbie_Scheme_ReportingEntityId_mbie_Report | C12: AMP WEALTH MANAGEMENT NEW ZEALAND LIMITED | D12: Reporting Period . sort descending Actions There are no records to display. | E12: There are no records to display. | F12: NEW ZEALAND RETIREMENT TRUST (SCH10911) | G12: No records | H12: Investment Scheme | K12: =VLOOKUP(B12,'20April'!B:G,6,0) -> No records
A13: 142 | B13: https://crd-app.companiesoffice.govt.nz/dashboard/reportingentity/scheme/?id=0b5ca035-8a94-ee11-be37-00224892b34a&refentity=mbie_reportingentity&refid=6b6c5ca5-8394-ee11-be37-00224892b34a&refrel=mbie_Scheme_ReportingEntityId_mbie_Report | C13: ANZ INVESTMENT SERVICES (NEW ZEALAND) LIMITED | D13: Reporting Period . sort descending Actions 31-03-2024 - Due by 31-07-2024 | E13: 31-03-2024 - Due by 31-07-2024 | F13: BONUS BONDS SCHEME (SCH11094) | G13: Have records but not submitted | H13: Investment Scheme | I13: 45382 | J13: 45504 | K13: =VLOOKUP(B13,'20April'!B:G,6,0) -> Have records but not submitted
A14: 143 | B14: https://crd-app.companiesoffice.govt.nz/dashboard/reportingentity/scheme/?id=115ca035-8a94-ee11-be37-00224892b34a&refentity=mbie_reportingentity&refid=6d6c5ca5-8394-ee11-be37-00224892b34a&refrel=mbie_Scheme_ReportingEntityId_mbie_Report | C14: ANZ NEW ZEALAND INVESTMENTS LIMITED | D14: Reporting Period . sort descending Actions 31-03-2024 - Due by 31-07-2024 | E14: 31-03-2024 - Due by 31-07-2024 | F14: ANZ DEFAULT KIWISAVER SCHEME (SCH11063) | G14: Have records but not submitted | H14: Investment Scheme | I14: 45382 | J14: 45504 | K14: =VLOOKUP(B14,'20April'!B:G,6,0) -> Have records but not submitted
A15: 145 | B15: https://crd-app.companiesoffice.govt.nz/dashboard/reportingentity/scheme/?id=155ca035-8a94-ee11-be37-00224892b34a&refentity=mbie_reportingentity&refid=6d6c5ca5-8394-ee11-be37-00224892b34a&refrel=mbie_Scheme_ReportingEntityId_mbie_Report | C15: ANZ NEW ZEALAND INVESTMENTS LIMITED | D15: Reporting Period . sort descending Actions 31-03-2024 - Due by 31-07-2024 | E15: 31-03-2024 - Due by 31-07-2024 | F15: ANZ INVESTMENTS SINGLE-ASSET-CLASS SCHEME (MARKETED AS THE ONEANSWER SINGLE-ASSET-CLASS FUNDS) (SCH11065) | G15: Have records but not submitted | H15: Investment Scheme | I15: 45382 | J15: 45504 | K15: =VLOOKUP(B15,'20April'!B:G,6,0) -> Have records but not submitted
A16: 146 | B16: https://crd-app.companiesoffice.govt.nz/dashboard/reportingentity/scheme/?id=0f5ca035-8a94-ee11-be37-00224892b34a&refentity=mbie_reportingentity&refid=6d6c5ca5-8394-ee11-be37-00224892b34a&refrel=mbie_Scheme_ReportingEntityId_mbie_Report | C16: ANZ NEW ZEALAND INVESTMENTS LIMITED | D16: Reporting Period . sort descending Actions 31-03-2024 - Due by 31-07-2024 | E16: 31-03-2024 - Due by 31-07-2024 | F16: ANZ KIWISAVER SCHEME (SCH11062) | G16: Have records but not submitted | H16: Investment Scheme | I16: 45382 | J16: 45504 | K16: =VLOOKUP(B16,'20April'!B:G,6,0) -> Have records but not submitted
A17: 147 | B17: https://crd-app.companiesoffice.govt.nz/dashboard/reportingentity/scheme/?id=0d5ca035-8a94-ee11-be37-00224892b34a&refentity=mbie_reportingentity&refid=6d6c5ca5-8394-ee11-be37-00224892b34a&refrel=mbie_Scheme_ReportingEntityId_mbie_Report | C17: ANZ NEW ZEALAND INVESTMENTS LIMITED | D17: Reporting Period . sort descending Actions 31-03-2024 - Due by 31-07-2024 | E17: 31-03-2024 - Due by 31-07-2024 | F17: ONEANSWER KIWISAVER SCHEME (SCH11061) | G17: Have records but not submitted | H17: Investment Scheme | I17: 45382 | J17: 45504 | K17: =VLOOKUP(B17,'20April'!B:G,6,0) -> Have records but not submitted
A18: 144 | B18: https://crd-app.companiesoffice.govt.nz/dashboard/reportingentity/scheme/?id=135ca035-8a94-ee11-be37-00224892b34a&refentity=mbie_reportingentity&refid=6d6c5ca5-8394-ee11-be37-00224892b34a&refrel=mbie_Scheme_ReportingEntityId_mbie_Report | C18: ANZ NEW ZEALAND INVESTMENTS LIMITED | D18: Reporting Period . sort descending Actions There are no records to display. | E18: There are no records to display. | F18: ANZ INVESTMENTS MULTI-ASSET-CLASS SCHEME (MARKETED AS THE ANZ INVESTMENT FUNDS AND ONEANSWER MULTI-ASSET-CLASS FUNDS) (SCH11064) | G18: No records | H18: Investment Scheme | K18: =VLOOKUP(B18,'20April'!B:G,6,0) -> No records
A19: 4 | B19: https://crd-app.companiesoffice.govt.nz/dashboard/reportingentity/?id=ad6b5ca5-8394-ee11-be37-00224892b34a | C19: ARBORGEN HOLDINGS LIMITED | D19: Reporting Period . sort descending Actions 31-03-2024 - Due by 31-07-2024 | E19: 31-03-2024 - Due by 31-07-2024 | G19: Have records but not submitted | H19: Company | I19: 45382 | J19: 45504 | K19: =VLOOKUP(B19,'20April'!B:G,6,0) -> Have records but not submitted
A20: 5 | B20: https://crd-app.companiesoffice.govt.nz/dashboard/reportingentity/?id=af6b5ca5-8394-ee11-be37-00224892b34a | C20: ARGOSY PROPERTY LIMITED | D20: Reporting Period . sort descending Actions 31-03-2024 - Due by 31-07-2024 | E20: 31-03-2024 - Due by 31-07-2024 | G20: Have records but not submitted | H20: Company | I20: 45382 | J20: 45504 | K20: =VLOOKUP(B20,'20April'!B:G,6,0) -> Have records but not submitted
A21: 6 | B21: https://crd-app.companiesoffice.govt.nz/dashboard/reportingentity/?id=b16b5ca5-8394-ee11-be37-00224892b34a | C21: ARVIDA GROUP LIMITED | D21: Reporting Period . sort descending Actions 31-03-2024 - Due by 31-07-2024 | E21: 31-03-2024 - Due by 31-07-2024 | G21: Have records but not submitted | H21: Company | I21: 45382 | J21: 45504 | K21: =VLOOKUP(B21,'20April'!B:G,6,0) -> Have records but not submitted
A22: 7 | B22: https://crd-app.companiesoffice.govt.nz/dashboard/reportingentity/?id=656b5ca5-8394-ee11-be37-00224892b34a | C22: ASB BANK LIMITED | D22: Reporting Period . sort descending Actions There are no records to display. | E22: There are no records to display. | G22: No records | H22: Company | K22: =VLOOKUP(B22,'20April'!B:G,6,0) -> No records
A23: 148 | B23: https://crd-app.companiesoffice.govt.nz/dashboard/reportingentity/scheme/?id=195ca035-8a94-ee11-be37-00224892b34a&refentity=mbie_reportingentity&refid=6f6c5ca5-8394-ee11-be37-00224892b34a&refrel=mbie_Scheme_ReportingEntityId_mbie_Report | C23: ASB GROUP INVESTMENTS LIMITED | D23: Reporting Period . sort descending Actions 31-03-2024 - Due by 31-07-2024 | E23: 31-03-2024 - Due by 31-07-2024 | F23: ASB INVESTMENT FUNDS (SCH10685) | G23: Have records but not submitted | H23: Investment Scheme | I23: 45382 | J23: 45504 | K23: =VLOOKUP(B23,'20April'!B:G,6,0) -> Have records but not submitted
A24: 149 | B24: https://crd-app.companiesoffice.govt.nz/dashboard/reportingentity/scheme/?id=175ca035-8a94-ee11-be37-00224892b34a&refentity=mbie_reportingentity&refid=6f6c5ca5-8394-ee11-be37-00224892b34a&refrel=mbie_Scheme_ReportingEntityId_mbie_Report | C24: ASB GROUP INVESTMENTS LIMITED | D24: Reporting Period . sort descending Actions 31-03-2024 - Due by 31-07-2024 | E24: 31-03-2024 - Due by 31-07-2024 | F24: ASB KIWISAVER SCHEME (SCH10678) | G24: Have records but not submitted | H24: Investment Scheme | I24: 45382 | J24: 45504 | K24: =VLOOKUP(B24,'20April'!B:G,6,0) -> Have records but not submitted
A25: 8 | B25: https://crd-app.companiesoffice.govt.nz/dashboard/reportingentity/?id=b36b5ca5-8394-ee11-be37-00224892b34a | C25: ASSET PLUS LIMITED | D25: Reporting Period . sort descending Actions 31-03-2024 - Due by 31-07-2024 | E25: 31-03-2024 - Due by 31-07-2024 | G25: Have records but not submitted | H25: Company | I25: 45382 | J25: 45504 | K25: =VLOOKUP(B25,'20April'!B:G,6,0) -> Have records but not submitted
A26: 9 | B26: https://crd-app.companiesoffice.govt.nz/dashboard/reportingentity/?id=8f6b5ca5-8394-ee11-be37-00224892b34a | C26: ASTERON LIFE LIMITED | D26: Reporting Period . sort descending Actions There are no records to display. | E26: There are no records to display. | G26: No records | H26: Company | K26: =VLOOKUP(B26,'20April'!B:G,6,0) -> No records
A27: 10 | B27: https://crd-app.companiesoffice.govt.nz/dashboard/reportingentity/?id=b56b5ca5-8394-ee11-be37-00224892b34a | C27: AUCKLAND COUNCIL | D27: Reporting Period . sort descending Actions There are no records to display. | E27: There are no records to display. | G27: No records | H27: Company | K27: =VLOOKUP(B27,'20April'!B:G,6,0) -> No records
A28: 11 | B28: https://crd-app.companiesoffice.govt.nz/dashboard/reportingentity/?id=b76b5ca5-8394-ee11-be37-00224892b34a | C28: AUCKLAND INTERNATIONAL AIRPORT LIMITED | D28: Reporting Period . sort descending Actions There are no records to display. | E28: There are no records to display. | G28: No records | H28: Company | K28: =VLOOKUP(B28,'20April'!B:G,6,0) -> No records
A29: 12 | B29: https://crd-app.companiesoffice.govt.nz/dashboard/reportingentity/?id=b96b5ca5-8394-ee11-be37-00224892b34a | C29: AUSTRALIAN FOUNDATION INVESTMENT COMPANY LIMITED | D29: Reporting Period . sort descending Actions There are no records to display. | E29: There are no records to display. | G29: No records | H29: Company | K29: =VLOOKUP(B29,'20April'!B:G,6,0) -> No records
A30: 13 | B30: https://crd-app.companiesoffice.govt.nz/dashboard/reportingentity/?id=676b5ca5-8394-ee11-be37-00224892b34a | C30: BANK OF CHINA (NEW ZEALAND) LIMITED | D30: Reporting Period . sort descending Actions 31-12-2023 - Click to view Climate Statement/s | E30: 31-12-2023 - Click to view Climate Statement/s | G30: Have records and have submitted | H30: Company | K30: =VLOOKUP(B30,'20April'!B:G,6,0) -> Have records but not submitted
A31: 14 | B31: https://crd-app.companiesoffice.govt.nz/dashboard/reportingentity/?id=696b5ca5-8394-ee11-be37-00224892b34a | C31: BANK OF CHINA LIMITED | D31: Reporting Period . sort descending Actions 31-12-2023 - Due by 30-04-2024 | E31: 31-12-2023 - Due by 30-04-2024 | G31: Have records but not submitted | H31: Company | I31: 45291 | J31: 45412 | K31: =VLOOKUP(B31,'20April'!B:G,6,0) -> Have records but not submitted
A32: 15 | B32: https://crd-app.companiesoffice.govt.nz/dashboard/reportingentity/?id=bb6b5ca5-8394-ee11-be37-00224892b34a | C32: BARRAMUNDI LIMITED | D32: Reporting Period . sort descending Actions There are no records to display. | E32: There are no records to display. | G32: No records | H32: Company | K32: =VLOOKUP(B32,'20April'!B:G,6,0) -> No records
A33: 150 | B33: https://crd-app.companiesoffice.govt.nz/dashboard/reportingentity/scheme/?id=1b5ca035-8a94-ee11-be37-00224892b34a&refentity=mbie_reportingentity&refid=716c5ca5-8394-ee11-be37-00224892b34a&refrel=mbie_Scheme_ReportingEntityId_mbie_Report | C33: BNZ INVESTMENT SERVICES LIMITED | D33: Reporting Period . sort descending Actions 31-03-2024 - Due by 31-07-2024 | E33: 31-03-2024 - Due by 31-07-2024 | F33: BNZ KIWISAVER SCHEME (SCH10701) | G33: Have records but not submitted | H33: Investment Scheme | I33: 45382 | J33: 45504 | K33: =VLOOKUP(B33,'20April'!B:G,6,0) -> Have records but not submitted
A34: 151 | B34: https://crd-app.companiesoffice.govt.nz/dashboard/reportingentity/scheme/?id=1d5ca035-8a94-ee11-be37-00224892b34a&refentity=mbie_reportingentity&refid=716c5ca5-8394-ee11-be37-00224892b34a&refrel=mbie_Scheme_ReportingEntityId_mbie_Report | C34: BNZ INVESTMENT SERVICES LIMITED | D34: Reporting Period . sort descending Actions 31-03-2024 - Due by 31-07-2024 | E34: 31-03-2024 - Due by 31-07-2024 | F34: PRIVATE WEALTH SERIES (SCH11384) | G34: Have records but not submitted | H34: Investment Scheme | I34: 45382 | J34: 45504 | K34: =VLOOKUP(B34,'20April'!B:G,6,0) -> Have records but not submitted
A35: 152 | B35: https://crd-app.companiesoffice.govt.nz/dashboard/reportingentity/scheme/?id=1f5ca035-8a94-ee11-be37-00224892b34a&refentity=mbie_reportingentity&refid=716c5ca5-8394-ee11-be37-00224892b34a&refrel=mbie_Scheme_ReportingEntityId_mbie_Report | C35: BNZ INVESTMENT SERVICES LIMITED | D35: Reporting Period . sort descending Actions 31-03-2024 - Due by 31-07-2024 | E35: 31-03-2024 - Due by 31-07-2024 | F35: YOUWEALTH (SCH12341) | G35: Have records but not submitted | H35: Investment Scheme | I35: 45382 | J35: 45504 | K35: =VLOOKUP(B35,'20April'!B:G,6,0) -> Have records but not submitted
A36: 153 | B36: https://crd-app.companiesoffice.govt.nz/dashboard/reportingentity/scheme/?id=295ca035-8a94-ee11-be37-00224892b34a&refentity=mbie_reportingentity&refid=736c5ca5-8394-ee11-be37-00224892b34a&refrel=mbie_Scheme_ReportingEntityId_mbie_Report | C36: BOOSTER INVESTMENT MANAGEMENT LIMITED | D36: Reporting Period . sort descending Actions 31-03-2024 - Due by 31-07-2024 | E36: 31-03-2024 - Due by 31-07-2024 | F36: BOOSTER INNOVATION SCHEME (SCH13202) | G36: Have records but not submitted | H36: Investment Scheme | I36: 45382 | J36: 45504 | K36: =VLOOKUP(B36,'20April'!B:G,6,0) -> Have records but not submitted
A37: 154 | B37: https://crd-app.companiesoffice.govt.nz/dashboard/reportingentity/scheme/?id=235ca035-8a94-ee11-be37-00224892b34a&refentity=mbie_reportingentity&refid=736c5ca5-8394-ee11-be37-00224892b34a&refrel=mbie_Scheme_ReportingEntityId_mbie_Report | C37: BOOSTER INVESTMENT MANAGEMENT LIMITED | D37: Reporting Period . sort descending Actions 31-03-2024 - Due by 31-07-2024 | E37: 31-03-2024 - Due by 31-07-2024 | F37: BOOSTER INVESTMENT SCHEME (SCH10844) | G37: Have records but not submitted | H37: Investment Scheme | I37: 45382 | J37: 45504 | K37: =VLOOKUP(B37,'20April'!B:G,6,0) -> Have records but not submitted
A38: 155 | B38: https://crd-app.companiesoffice.govt.nz/dashboard/reportingentity/scheme/?id=275ca035-8a94-ee11-be37-00224892b34a&refentity=mbie_reportingentity&refid=736c5ca5-8394-ee11-be37-00224892b34a&refrel=mbie_Scheme_ReportingEntityId_mbie_Report | C38: BOOSTER INVESTMENT MANAGEMENT LIMITED | D38: Reporting Period . sort descending Actions 31-03-2024 - Due by 31-07-2024 | E38: 31-03-2024 - Due by 31-07-2024 | F38: BOOSTER INVESTMENT SCHEME 2 (SCH12548) | G38: Have records but not submitted | H38: Investment Scheme | I38: 45382 | J38: 45504 | K38: =VLOOKUP(B38,'20April'!B:G,6,0) -> Have records but not submitted
A39: 156 | B39: https://crd-app.companiesoffice.govt.nz/dashboard/reportingentity/scheme/?id=215ca035-8a94-ee11-be37-00224892b34a&refentity=mbie_reportingentity&refid=736c5ca5-8394-ee11-be37-00224892b34a&refrel=mbie_Scheme_ReportingEntityId_mbie_Report | C39: BOOSTER INVESTMENT MANAGEMENT LIMITED | D39: Reporting Period . sort descending Actions 31-03-2024 - Due by 31-07-2024 | E39: 31-03-2024 - Due by 31-07-2024 | F39: BOOSTER KIWISAVER SCHEME (SCH10841) | G39: Have records but not submitted | H39: Investment Scheme | I39: 45382 | J39: 45504 | K39: =VLOOKUP(B39,'20April'!B:G,6,0) -> Have records but not submitted
A40: 157 | B40: https://crd-app.companiesoffice.govt.nz/dashboard/reportingentity/scheme/?id=2b5ca035-8a94-ee11-be37-00224892b34a&refentity=mbie_reportingentity&refid=736c5ca5-8394-ee11-be37-00224892b34a&refrel=mbie_Scheme_ReportingEntityId_mbie_Report | C40: BOOSTER INVESTMENT MANAGEMENT LIMITED | D40: Reporting Period . sort descending Actions 31-03-2024 - Due by 31-07-2024 | E40: 31-03-2024 - Due by 31-07-2024 | F40: BOOSTER SAVVY SCHEME (SCH13546) | G40: Have records but not submitted | H40: Investment Scheme | I40: 45382 | J40: 45504 | K40: =VLOOKUP(B40,'20April'!B:G,6,0) -> Have records but not submitted
...

Sheet 2.masterfirm
A1: Company Name | B1: scheme | C1: industry | D1: industry_large group | E1: count_firm | F1: count | G1: status | H1: duedate | I1: duemonth
A2: AA INSURANCE LIMITED | B2: Company | C2: Insurance | D2: Financial Sector | E2: 1 | F2: =COUNTIFS('1.master_list_7May'!C:C,A2) -> 1 | G2: =VLOOKUP($A2,'1.master_list_7May'!C:G,5,0) -> No records | I2: =IF(H2=0,"No month", MONTH(H2)) -> No month
A3: AFT PHARMACEUTICALS LIMITED | B3: Company | C3: Healthcare | D3: Other | E3: 1 | F3: =COUNTIFS('1.master_list_7May'!C:C,A3) -> 1 | G3: =VLOOKUP($A3,'1.master_list_7May'!C:G,5,0) -> Have records but not submitted | H3: =VLOOKUP(A3,'1.master_list_7May'!C:J,8,0) -> 45504 | I3: =IF(H3=0,"No month", MONTH(H3)) -> 7
A4: AIA NEW ZEALAND LIMITED | B4: Company | C4: Insurance | D4: Financial Sector | E4: 1 | F4: =COUNTIFS('1.master_list_7May'!C:C,A4) -> 1 | G4: =VLOOKUP($A4,'1.master_list_7May'!C:G,5,0) -> Have records and have submitted | I4: =IF(H4=0,"No month", MONTH(H4)) -> No month
A5: AIR NEW ZEALAND LIMITED | B5: Company | C5: Airport/Infrastructure | D5: Other | E5: 1 | F5: =COUNTIFS('1.master_list_7May'!C:C,A5) -> 1 | G5: =VLOOKUP($A5,'1.master_list_7May'!C:G,5,0) -> No records | I5: =IF(H5=0,"No month", MONTH(H5)) -> No month
A6: AMP WEALTH MANAGEMENT NEW ZEALAND LIMITED | B6: Investment Scheme | C6: Finance/Investment | D6: Financial Sector | E6: 1 | F6: =COUNTIFS('1.master_list_7May'!C:C,A6) -> 7 | G6: =VLOOKUP($A6,'1.master_list_7May'!C:G,5,0) -> Have records but not submitted | H6: =VLOOKUP(A6,'1.master_list_7May'!C:J,8,0) -> 45504 | I6: =IF(H6=0,"No month", MONTH(H6)) -> 7
A7: ANZ INVESTMENT SERVICES (NEW ZEALAND) LIMITED | B7: Investment Scheme | C7: Finance/Investment | D7: Financial Sector | E7: 1 | F7: =COUNTIFS('1.master_list_7May'!C:C,A7) -> 1 | G7: =VLOOKUP($A7,'1.master_list_7May'!C:G,5,0) -> Have records but not submitted | H7: =VLOOKUP(A7,'1.master_list_7May'!C:J,8,0) -> 45504 | I7: =IF(H7=0,"No month", MONTH(H7)) -> 7
A8: ANZ NEW ZEALAND INVESTMENTS LIMITED | B8: Investment Scheme | C8: Australian/Nz Bank | D8: Financial Sector | E8: 1 | F8: =COUNTIFS('1.master_list_7May'!C:C,A8) -> 5 | G8: =VLOOKUP($A8,'1.master_list_7May'!C:G,5,0) -> Have records but not submitted | H8: =VLOOKUP(A8,'1.master_list_7May'!C:J,8,0) -> 45504 | I8: =IF(H8=0,"No month", MONTH(H8)) -> 7
A9: ARBORGEN HOLDINGS LIMITED | B9: Company | C9: Finance/Investment | D9: Financial Sector | E9: 1 | F9: =COUNTIFS('1.master_list_7May'!C:C,A9) -> 1 | G9: =VLOOKUP($A9,'1.master_list_7May'!C:G,5,0) -> Have records but not submitted | H9: =VLOOKUP(A9,'1.master_list_7May'!C:J,8,0) -> 45504 | I9: =IF(H9=0,"No month", MONTH(H9)) -> 7
A10: ARGOSY PROPERTY LIMITED | B10: Company | C10: Property | D10: Real Estate | E10: 1 | F10: =COUNTIFS('1.master_list_7May'!C:C,A10) -> 1 | G10: =VLOOKUP($A10,'1.master_list_7May'!C:G,5,0) -> Have records but not submitted | H10: =VLOOKUP(A10,'1.master_list_7May'!C:J,8,0) -> 45504 | I10: =IF(H10=0,"No month", MONTH(H10)) -> 7
A11: ARVIDA GROUP LIMITED | B11: Company | C11: Property | D11: Real Estate | E11: 1 | F11: =COUNTIFS('1.master_list_7May'!C:C,A11) -> 1 | G11: =VLOOKUP($A11,'1.master_list_7May'!C:G,5,0) -> Have records but not submitted | H11: =VLOOKUP(A11,'1.master_list_7May'!C:J,8,0) -> 45504 | I11: =IF(H11=0,"No month", MONTH(H11)) -> 7
A12: ASB BANK LIMITED | B12: Company | C12: Australian/Nz Bank | D12: Financial Sector | E12: 1 | F12: =COUNTIFS('1.master_list_7May'!C:C,A12) -> 1 | G12: =VLOOKUP($A12,'1.master_list_7May'!C:G,5,0) -> No records | I12: =IF(H12=0,"No month", MONTH(H12)) -> No month
A13: ASB GROUP INVESTMENTS LIMITED | B13: Investment Scheme | C13: Finance/Investment | D13: Financial Sector | E13: 1 | F13: =COUNTIFS('1.master_list_7May'!C:C,A13) -> 2 | G13: =VLOOKUP($A13,'1.master_list_7May'!C:G,5,0) -> Have records but not submitted | H13: =VLOOKUP(A13,'1.master_list_7May'!C:J,8,0) -> 45504 | I13: =IF(H13=0,"No month", MONTH(H13)) -> 7
A14: ASSET PLUS LIMITED | B14: Company | C14: Finance/Investment | D14: Financial Sector | E14: 1 | F14: =COUNTIFS('1.master_list_7May'!C:C,A14) -> 1 | G14: =VLOOKUP($A14,'1.master_list_7May'!C:G,5,0) -> Have records but not submitted | H14: =VLOOKUP(A14,'1.master_list_7May'!C:J,8,0) -> 45504 | I14: =IF(H14=0,"No month", MONTH(H14)) -> 7
A15: ASTERON LIFE LIMITED | B15: Company | C15: Insurance | D15: Financial Sector | E15: 1 | F15: =COUNTIFS('1.master_list_7May'!C:C,A15) -> 1 | G15: =VLOOKUP($A15,'1.master_list_7May'!C:G,5,0) -> No records | I15: =IF(H15=0,"No month", MONTH(H15)) -> No month
A16: AUCKLAND COUNCIL | B16: Company | C16: Government | D16: Other | E16: 1 | F16: =COUNTIFS('1.master_list_7May'!C:C,A16) -> 1 | G16: =VLOOKUP($A16,'1.master_list_7May'!C:G,5,0) -> No records | I16: =IF(H16=0,"No month", MONTH(H16)) -> No month
A17: AUCKLAND INTERNATIONAL AIRPORT LIMITED | B17: Company | C17: Airport/Infrastructure | D17: Other | E17: 1 | F17: =COUNTIFS('1.master_list_7May'!C:C,A17) -> 1 | G17: =VLOOKUP($A17,'1.master_list_7May'!C:G,5,0) -> No records | I17: =IF(H17=0,"No month", MONTH(H17)) -> No month
A18: AUSTRALIAN FOUNDATION INVESTMENT COMPANY LIMITED | B18: Company | C18: Finance/Investment | D18: Financial Sector | E18: 1 | F18: =COUNTIFS('1.master_list_7May'!C:C,A18) -> 1 | G18: =VLOOKUP($A18,'1.master_list_7May'!C:G,5,0) -> No records | I18: =IF(H18=0,"No month", MONTH(H18)) -> No month
A19: BANK OF CHINA (NEW ZEALAND) LIMITED | B19: Company | C19: Foreign Bank | D19: Financial Sector | E19: 1 | F19: =COUNTIFS('1.master_list_7May'!C:C,A19) -> 1 | G19: =VLOOKUP($A19,'1.master_list_7May'!C:G,5,0) -> Have records and have submitted | I19: =IF(H19=0,"No month", MONTH(H19)) -> No month
A20: BANK OF CHINA LIMITED | B20: Company | C20: Foreign Bank | D20: Financial Sector | E20: 1 | F20: =COUNTIFS('1.master_list_7May'!C:C,A20) -> 1 | G20: =VLOOKUP($A20,'1.master_list_7May'!C:G,5,0) -> Have records but not submitted | H20: =VLOOKUP(A20,'1.master_list_7May'!C:J,8,0) -> 45412 | I20: =IF(H20=0,"No month", MONTH(H20)) -> 4
A21: BARRAMUNDI LIMITED | B21: Company | C21: Finance/Investment | D21: Financial Sector | E21: 1 | F21: =COUNTIFS('1.master_list_7May'!C:C,A21) -> 1 | G21: =VLOOKUP($A21,'1.master_list_7May'!C:G,5,0) -> No records | I21: =IF(H21=0,"No month", MONTH(H21)) -> No month
A22: BNZ INVESTMENT SERVICES LIMITED | B22: Investment Scheme | C22: Finance/Investment | D22: Financial Sector | E22: 1 | F22: =COUNTIFS('1.master_list_7May'!C:C,A22) -> 3 | G22: =VLOOKUP($A22,'1.master_list_7May'!C:G,5,0) -> Have records but not submitted | H22: =VLOOKUP(A22,'1.master_list_7May'!C:J,8,0) -> 45504 | I22: =IF(H22=0,"No month", MONTH(H22)) -> 7
A23: BOOSTER INVESTMENT MANAGEMENT LIMITED | B23: Investment Scheme | C23: Finance/Investment | D23: Financial Sector | E23: 1 | F23: =COUNTIFS('1.master_list_7May'!C:C,A23) -> 6 | G23: =VLOOKUP($A23,'1.master_list_7May'!C:G,5,0) -> Have records but not submitted | H23: =VLOOKUP(A23,'1.master_list_7May'!C:J,8,0) -> 45504 | I23: =IF(H23=0,"No month", MONTH(H23)) -> 7
A24: BRISCOE GROUP LIMITED | B24: Company | C24: Consumer | D24: Industry | E24: 1 | F24: =COUNTIFS('1.master_list_7May'!C:C,A24) -> 1 | G24: =VLOOKUP($A24,'1.master_list_7May'!C:G,5,0) -> Have records and have submitted | I24: =IF(H24=0,"No month", MONTH(H24)) -> No month
A25: BT FUNDS MANAGEMENT (NZ) LIMITED | B25: Investment Scheme | C25: Finance/Investment | D25: Financial Sector | E25: 1 | F25: =COUNTIFS('1.master_list_7May'!C:C,A25) -> 4 | G25: =VLOOKUP($A25,'1.master_list_7May'!C:G,5,0) -> Have records but not submitted | H25: =VLOOKUP(A25,'1.master_list_7May'!C:J,8,0) -> 45504 | I25: =IF(H25=0,"No month", MONTH(H25)) -> 7
A26: CDL INVESTMENTS NEW ZEALAND LIMITED | B26: Company | C26: Finance/Investment | D26: Financial Sector | E26: 1 | F26: =COUNTIFS('1.master_list_7May'!C:C,A26) -> 1 | G26: =VLOOKUP($A26,'1.master_list_7May'!C:G,5,0) -> Have records and have submitted | I26: =IF(H26=0,"No month", MONTH(H26)) -> No month
A27: CENTURIA FUNDS MANAGEMENT (NZ) LIMITED | B27: Investment Scheme | C27: Finance/Investment | D27: Financial Sector | E27: 1 | F27: =COUNTIFS('1.master_list_7May'!C:C,A27) -> 24 | G27: =VLOOKUP($A27,'1.master_list_7May'!C:G,5,0) -> Have records but not submitted | H27: =VLOOKUP(A27,'1.master_list_7May'!C:J,8,0) -> 45504 | I27: =IF(H27=0,"No month", MONTH(H27)) -> 7
A28: CHANNEL INFRASTRUCTURE NZ LIMITED | B28: Company | C28: Airport/Infrastructure | D28: Industry | E28: 1 | F28: =COUNTIFS('1.master_list_7May'!C:C,A28) -> 1 | G28: =VLOOKUP($A28,'1.master_list_7May'!C:G,5,0) -> Have records and have submitted | I28: =IF(H28=0,"No month", MONTH(H28)) -> No month
A29: CHINA CONSTRUCTION BANK (NEW ZEALAND) LIMITED | B29: Company | C29: Foreign Bank | D29: Financial Sector | E29: 1 | F29: =COUNTIFS('1.master_list_7May'!C:C,A29) -> 1 | G29: =VLOOKUP($A29,'1.master_list_7May'!C:G,5,0) -> Have records and have submitted | I29: =IF(H29=0,"No month", MONTH(H29)) -> No month
A30: CHINA CONSTRUCTION BANK CORPORATION | B30: Company | C30: Foreign Bank | D30: Financial Sector | E30: 1 | F30: =COUNTIFS('1.master_list_7May'!C:C,A30) -> 1 | G30: =VLOOKUP($A30,'1.master_list_7May'!C:G,5,0) -> Have records and have submitted | I30: =IF(H30=0,"No month", MONTH(H30)) -> No month
A31: CHORUS LIMITED | B31: Company | C31: Telecommunications | D31: It | E31: 1 | F31: =COUNTIFS('1.master_list_7May'!C:C,A31) -> 1 | G31: =VLOOKUP($A31,'1.master_list_7May'!C:G,5,0) -> No records | I31: =IF(H31=0,"No month", MONTH(H31)) -> No month
A32: CHRISTCHURCH CITY HOLDINGS LIMITED | B32: Company | C32: Finance/Investment | D32: Financial Sector | E32: 1 | F32: =COUNTIFS('1.master_list_7May'!C:C,A32) -> 1 | G32: =VLOOKUP($A32,'1.master_list_7May'!C:G,5,0) -> No records | I32: =IF(H32=0,"No month", MONTH(H32)) -> No month
A33: CHRISTCHURCH INTERNATIONAL AIRPORT LIMITED | B33: Company | C33: Airport/Infrastructure | D33: Other | E33: 1 | F33: =COUNTIFS('1.master_list_7May'!C:C,A33) -> 1 | G33: =VLOOKUP($A33,'1.master_list_7May'!C:G,5,0) -> No records | I33: =IF(H33=0,"No month", MONTH(H33)) -> No month
A34: CHUBB LIFE INSURANCE NEW ZEALAND LIMITED | B34: Company | C34: Insurance | D34: Financial Sector | E34: 1 | F34: =COUNTIFS('1.master_list_7May'!C:C,A34) -> 1 | G34: =VLOOKUP($A34,'1.master_list_7May'!C:G,5,0) -> Have records and have submitted | I34: =IF(H34=0,"No month", MONTH(H34)) -> No month
A35: CITIBANK, N.A. | B35: Company | C35: Foreign Bank | D35: Financial Sector | E35: 1 | F35: =COUNTIFS('1.master_list_7May'!C:C,A35) -> 1 | G35: =VLOOKUP($A35,'1.master_list_7May'!C:G,5,0) -> Have records and have submitted | I35: =IF(H35=0,"No month", MONTH(H35)) -> No month
A36: COMMONWEALTH BANK OF AUSTRALIA | B36: Company | C36: Australian/Nz Bank | D36: Financial Sector | E36: 1 | F36: =COUNTIFS('1.master_list_7May'!C:C,A36) -> 1 | G36: =VLOOKUP($A36,'1.master_list_7May'!C:G,5,0) -> No records | I36: =IF(H36=0,"No month", MONTH(H36)) -> No month
A37: COMVITA LIMITED | B37: Company | C37: Food/Agriculture | D37: Food/Agricuture | E37: 1 | F37: =COUNTIFS('1.master_list_7May'!C:C,A37) -> 1 | G37: =VLOOKUP($A37,'1.master_list_7May'!C:G,5,0) -> No records | I37: =IF(H37=0,"No month", MONTH(H37)) -> No month
A38: CONTACT ENERGY LIMITED | B38: Company | C38: Energy | D38: Energy | E38: 1 | F38: =COUNTIFS('1.master_list_7May'!C:C,A38) -> 1 | G38: =VLOOKUP($A38,'1.master_list_7May'!C:G,5,0) -> No records | I38: =IF(H38=0,"No month", MONTH(H38)) -> No month
A39: COOPERATIEVE RABOBANK U.A. | B39: Company | C39: Australian/Nz Bank | D39: Financial Sector | E39: 1 | F39: =COUNTIFS('1.master_list_7May'!C:C,A39) -> 1 | G39: =VLOOKUP($A39,'1.master_list_7May'!C:G,5,0) -> Have records and have submitted | I39: =IF(H39=0,"No month", MONTH(H39)) -> No month
... A41: EBOS GROUP LIMITED | B41: Company | C41: Healthcare | D41: Other | E41: 1 | F41: =COUNTIFS('1.master_list_7May'!C:C,A41) -> 1 | G41: =VLOOKUP($A41,'1.master_list_7May'!C:G,5,0) -> No records | I41: =IF(H41=0,"No month", MONTH(H41)) -> No month
...

Sheet 3.simple_text_analysis
B1: file_name | C1: pages_num | D1: number_characters | E1: number_words | F1: negative | G1: neutral | H1: positive | I1: compound | J1: readable | K1: company | L1: statement | M1: industry | N1: industry_large group | O1: status | P1: category
A2: 0 | B2: 2023 12 31 - PFI - Climate-related Disclosures - Signed.pdf | C2: 35 | D2: 101572 | E2: 13659 | F2: 0.08 | G2: 0.825 | H2: 0.094 | I2: 0.9997 | J2: Readable | K2: PROPERTY FOR INDUSTRY LIMITED | L2: statement | M2: =VLOOKUP(K2,'2.masterfirm'!A:D,3,0) -> Property | N2: =VLOOKUP(K2,'2.masterfirm'!A:D,4,0) -> Real Estate | O2: =IFERROR(VLOOKUP(K2,'1.master_list_7May'!C:K,9,0),"") -> Have records and have submitted | P2: climate statement
A3: 1 | B3: 2023 Climate Statements for Citibank N.A. (New Zealand Branch).pdf | C3: 51 | D3: 95807 | E3: 13761 | F3: 0.078 | G3: 0.845 | H3: 0.077 | I3: -0.9404 | J3: Readable | K3: CITIBANK, N.A. | L3: statement | M3: =VLOOKUP(K3,'2.masterfirm'!A:D,3,0) -> Foreign Bank | N3: =VLOOKUP(K3,'2.masterfirm'!A:D,4,0) -> Financial Sector | O3: =IFERROR(VLOOKUP(K3,'1.master_list_7May'!C:K,9,0),"") -> Have records but not submitted | P3: climate statement
A4: 2 | B4: AIA NZ Climate Related Disclosers Report FINAL_signed.pdf | C4: 23 | D4: 60167 | E4: 8354 | F4: 0.06 | G4: 0.847 | H4: 0.093 | I4: 0.9998 | J4: Readable | K4: AIA NEW ZEALAND LIMITED | L4: statement | M4: =VLOOKUP(K4,'2.masterfirm'!A:D,3,0) -> Insurance | N4: =VLOOKUP(K4,'2.masterfirm'!A:D,4,0) -> Financial Sector | O4: =IFERROR(VLOOKUP(K4,'1.master_list_7May'!C:K,9,0),"") -> Have records but not submitted | P4: climate statement
A5: 3 | B5: ANZ_climate-report-2023.pdf | J5: Nonreadable | K5: ANZ NEW ZEALAND INVESTMENTS LIMITED | L5: statement | M5: =VLOOKUP(K5,'2.masterfirm'!A:D,3,0) -> Australian/Nz Bank | N5: =VLOOKUP(K5,'2.masterfirm'!A:D,4,0) -> Financial Sector | O5: =IFERROR(VLOOKUP(K5,'1.master_list_7May'!C:K,9,0),"") -> Have records but not submitted | P5: climate statement
A6: 4 | B6: asb-climate-report-2022.pdf | J6: Nonreadable | K6: ASB BANK LIMITED | L6: statement | M6: =VLOOKUP(K6,'2.masterfirm'!A:D,3,0) -> Australian/Nz Bank | N6: =VLOOKUP(K6,'2.masterfirm'!A:D,4,0) -> Financial Sector | O6: =IFERROR(VLOOKUP(K6,'1.master_list_7May'!C:K,9,0),"") -> No records | P6: climate statement
A7: 5 | B7: Bank of China (New Zealand) Limited Climate Related Disclosure for the year ended 31 December 2023.pdf | C7: 22 | D7: 53361 | E7: 6502 | F7: 0.08 | G7: 0.857 | H7: 0.063 | I7: -0.9983 | J7: Readable | K7: BANK OF CHINA (NEW ZEALAND) LIMITED | L7: statement | M7: =VLOOKUP(K7,'2.masterfirm'!A:D,3,0) -> Foreign Bank | N7: =VLOOKUP(K7,'2.masterfirm'!A:D,4,0) -> Financial Sector | O7: =IFERROR(VLOOKUP(K7,'1.master_list_7May'!C:K,9,0),"") -> Have records but not submitted | P7: climate statement
A8: 6 | B8: Bank of China New Zealand Banking Group Climate Related Disclosure for the year ended 31 December 2023.pdf.pdf | C8: 22 | D8: 51228 | E8: 6245 | F8: 0.077 | G8: 0.86 | H8: 0.063 | I8: -0.9968 | J8: Readable | K8: BANK OF CHINA (NEW ZEALAND) LIMITED | L8: statement | M8: =VLOOKUP(K8,'2.masterfirm'!A:D,3,0) -> Foreign Bank | N8: =VLOOKUP(K8,'2.masterfirm'!A:D,4,0) -> Financial Sector | O8: =IFERROR(VLOOKUP(K8,'1.master_list_7May'!C:K,9,0),"") -> Have records but not submitted | P8: climate statement
A9: 7 | B9: BNZ_2023-Climate-Report.pdf | C9: 59 | D9: 208049 | E9: 27829 | F9: 0.082 | G9: 0.853 | H9: 0.065 | I9: -0.9999 | J9: Readable | K9: BNZ INVESTMENT SERVICES LIMITED | L9: statement | M9: =VLOOKUP(K9,'2.masterfirm'!A:D,3,0) -> Finance/Investment | N9: =VLOOKUP(K9,'2.masterfirm'!A:D,4,0) -> Financial Sector | O9: =IFERROR(VLOOKUP(K9,'1.master_list_7May'!C:K,9,0),"") -> Have records but not submitted | P9: climate statement
A10: 8 | B10: Briscoe Group 2024 Annual Report.pdf | C10: 94 | D10: 247464 | E10: 40464 | F10: 0.053 | G10: 0.815 | H10: 0.132 | I10: 1 | J10: Readable | K10: BRISCOE GROUP LIMITED | L10: statement | M10: =VLOOKUP(K10,'2.masterfirm'!A:D,3,0) -> Consumer | N10: =VLOOKUP(K10,'2.masterfirm'!A:D,4,0) -> Industry | O10: =IFERROR(VLOOKUP(K10,'1.master_list_7May'!C:K,9,0),"") -> Have records and have submitted | P10: Annual report
A11: 9 | B11: CCBNZBG Climate Report for the year ended 31 December 2023.pdf | J11: Nonreadable | K11: CHINA CONSTRUCTION BANK (NEW ZEALAND) LIMITED | L11: statement | M11: =VLOOKUP(K11,'2.masterfirm'!A:D,3,0) -> Foreign Bank | N11: =VLOOKUP(K11,'2.masterfirm'!A:D,4,0) -> Financial Sector | O11: =IFERROR(VLOOKUP(K11,'1.master_list_7May'!C:K,9,0),"") -> Have records but not submitted | P11: climate statement
A12: 10 | B12: CCBNZL Climate Report for the year ended 31 December 2023.pdf | J12: Nonreadable | K12: CHINA CONSTRUCTION BANK (NEW ZEALAND) LIMITED | L12: statement | M12: =VLOOKUP(K12,'2.masterfirm'!A:D,3,0) -> Foreign Bank | N12: =VLOOKUP(K12,'2.masterfirm'!A:D,4,0) -> Financial Sector | O12: =IFERROR(VLOOKUP(K12,'1.master_list_7May'!C:K,9,0),"") -> Have records but not submitted | P12: climate statement
A13: 11 | B13: CDL0017_Climate_Related_Disclosures_2023.pdf | C13: 12 | D13: 57241 | E13: 8643 | F13: 0.064 | G13: 0.853 | H13: 0.083 | I13: 0.9994 | J13: Readable | K13: CDL INVESTMENTS NEW ZEALAND LIMITED | L13: statement | M13: =VLOOKUP(K13,'2.masterfirm'!A:D,3,0) -> Finance/Investment | N13: =VLOOKUP(K13,'2.masterfirm'!A:D,4,0) -> Financial Sector | O13: =IFERROR(VLOOKUP(K13,'1.master_list_7May'!C:K,9,0),"") -> Have records and have submitted | P13: climate statement
A14: 12 | B14: Chubb Life Insurance New Zealand Limited Climate Disclosure 2023.pdf | C14: 23 | D14: 69324 | E14: 10179 | F14: 0.068 | G14: 0.841 | H14: 0.092 | I14: 0.9998 | J14: Readable | K14: CHUBB LIFE INSURANCE NEW ZEALAND LIMITED | L14: statement | M14: =VLOOKUP(K14,'2.masterfirm'!A:D,3,0) -> Insurance | N14: =VLOOKUP(K14,'2.masterfirm'!A:D,4,0) -> Financial Sector | O14: =IFERROR(VLOOKUP(K14,'1.master_list_7May'!C:K,9,0),"") -> Have records but not submitted | P14: climate statement
